<?xml version="1.0" ?>
<robot name="codian" xmlns:xacro="http://ros.org/wiki/xacro">
  <link name="world"/>
  <joint name="base" type="fixed">
    <parent link="world"/>
    <child link="base_link"/>
    <axis xyz="0 0 0"/>
    <origin rpy="0 0 0" xyz="0 0 2"/>
  </joint>
  <gazebo reference="link_w_JOINT_w2">
    <physics>
      <ode>
        <provide_feedback>true</provide_feedback>
      </ode>
    </physics>
  </gazebo>
  <link name="base_link">
    <inertial>
      <origin rpy="0 0 0" xyz="0 0 0"/>
      <mass value="0.00001"/>
      <inertia ixx="0.00001" ixy="0.0" ixz="0.0" iyy="0.00001" iyz="0.0" izz="0.00001"/>
    </inertial>
    <visual>
      <origin rpy="0 0 0" xyz="0 0 0"/>
      <geometry>
        <mesh filename="/home/remco/catkin_ws/src/delta_robot_simulation/meshes/base_link.dae" scale="0.001 0.001 0.001"/>
      </geometry>
    </visual>
    <collision>
      <origin rpy="0 0 0" xyz="0 0 0"/>
      <geometry>
        <mesh filename="/home/remco/catkin_ws/src/delta_robot_simulation/meshes/base_link.dae" scale="0.001 0.001 0.001"/>
      </geometry>
    </collision>
  </link>
  <gazebo reference="base_link">
    <visual>
      <material>
        <script>
          <uri>file://media/materials/scripts/gazebo.material</uri>
          <name>Gazebo/Red</name>
        </script>
      </material>
    </visual>
  </gazebo>
  <gazebo reference="uleg_1">
    <visual>
      <material>
        <script>
          <uri>file://media/materials/scripts/gazebo.material</uri>
          <name>Gazebo/Green</name>
        </script>
      </material>
    </visual>
  </gazebo>
  <gazebo reference="uleg_2">
    <visual>
      <material>
        <script>
          <uri>file://media/materials/scripts/gazebo.material</uri>
          <name>Gazebo/Green</name>
        </script>
      </material>
    </visual>
  </gazebo>
  <gazebo reference="uleg_3">
    <visual>
      <material>
        <script>
          <uri>file://media/materials/scripts/gazebo.material</uri>
          <name>Gazebo/Green</name>
        </script>
      </material>
    </visual>
  </gazebo>
  <gazebo reference="low_base">
    <visual>
      <material>
        <script>
          <uri>file://media/materials/scripts/gazebo.material</uri>
          <name>Gazebo/Blue</name>
        </script>
      </material>
    </visual>
  </gazebo>
  <joint name="motor1" type="revolute">
    <origin rpy="0 0 0" xyz="0 -0.2 0"/>
    <parent link="base_link"/>
    <child link="uleg_1"/>
    <limit effort="1000" lower="-0.820" upper="1.727" velocity="10"/>
    <axis xyz="1 0 0"/>
  </joint>
  <joint name="motor2" type="revolute">
    <origin rpy="0 0 4.1887902048" xyz="-0.1732050 0.100 0"/>
    <parent link="base_link"/>
    <child link="uleg_2"/>
    <limit effort="1000" lower="-0.820" upper="1.727" velocity="10"/>
    <axis xyz="1 0 0"/>
  </joint>
  <joint name="motor3" type="revolute">
    <origin rpy="0 0 2.0943951024" xyz="0.1732050 0.100 0"/>
    <parent link="base_link"/>
    <child link="uleg_3"/>
    <limit effort="1000" lower="-0.820" upper="1.727" velocity="10"/>
    <axis xyz="1 0 0"/>
  </joint>
  <link name="uleg_1">
    <inertial>
      <origin rpy="0 0 0" xyz="-0.044 0 0"/>
      <mass value="0.00001"/>
      <inertia ixx="0.00001" ixy="0.0" ixz="0.0" iyy="0.00001" iyz="0.0" izz="0.00001"/>
    </inertial>
    <visual>
      <origin rpy="0 0 0" xyz="-0.044 0 0"/>
      <geometry>
        <mesh filename="/home/remco/catkin_ws/src/delta_robot_simulation/meshes/uleg_link.dae" scale="0.001 0.001 0.001"/>
      </geometry>
    </visual>
    <collision>
      <origin rpy="0 0 0" xyz="-0.044 0 0"/>
      <geometry>
        <mesh filename="/home/remco/catkin_ws/src/delta_robot_simulation/meshes/uleg_link.dae" scale="0.001 0.001 0.001"/>
      </geometry>
    </collision>
  </link>
  <link name="uleg_2">
    <inertial>
      <origin rpy="0 0 0" xyz="-0.044 0 0"/>
      <mass value="0.00001"/>
      <inertia ixx="0.00001" ixy="0.0" ixz="0.0" iyy="0.00001" iyz="0.0" izz="0.00001"/>
    </inertial>
    <visual>
      <origin rpy="0 0 0" xyz="-0.044 0 0"/>
      <geometry>
        <mesh filename="/home/remco/catkin_ws/src/delta_robot_simulation/meshes/uleg_link.dae" scale="0.001 0.001 0.001"/>
      </geometry>
    </visual>
    <collision>
      <origin rpy="0 0 0" xyz="-0.044 0 0"/>
      <geometry>
        <mesh filename="/home/remco/catkin_ws/src/delta_robot_simulation/meshes/uleg_link.dae" scale="0.001 0.001 0.001"/>
      </geometry>
    </collision>
  </link>
  <link name="uleg_3">
    <inertial>
      <origin rpy="0 0 0" xyz="-0.044 0 0"/>
      <mass value="0.00001"/>
      <inertia ixx="0.00001" ixy="0.0" ixz="0.0" iyy="0.00001" iyz="0.0" izz="0.00001"/>
    </inertial>
    <visual>
      <origin rpy="0 0 0" xyz="-0.044 0 0"/>
      <geometry>
        <mesh filename="/home/remco/catkin_ws/src/delta_robot_simulation/meshes/uleg_link.dae" scale="0.001 0.001 0.001"/>
      </geometry>
    </visual>
    <collision>
      <origin rpy="0 0 0" xyz="-0.044 0 0"/>
      <geometry>
        <mesh filename="/home/remco/catkin_ws/src/delta_robot_simulation/meshes/uleg_link.dae" scale="0.001 0.001 0.001"/>
      </geometry>
    </collision>
  </link>
<!--lleg1-->
  <joint name="con_lleg_1" type="continuous">
    <origin rpy="0.585890011 0 0" xyz="0.052 -0.320 0"/>
    <parent link="uleg_1"/>
    <child link="lleg_1"/>
    <axis xyz="1 1 1"/>
  </joint>
  <link name="lleg_1">
    <inertial>
      <origin rpy="-1.5707963268 0 0" xyz="0 0 0 "/>
      <mass value="0.00001"/>
      <inertia ixx="0.00001" ixy="0.0" ixz="0.0" iyy="0.00001" iyz="0.0" izz="0.00001"/>
    </inertial>
    <visual>
      <origin rpy="-1.5707963268 0 0" xyz="0 0 0"/>
      <geometry>
        <mesh filename="/home/remco/catkin_ws/src/delta_robot_simulation/meshes/lleg_link.dae" scale="0.001 0.001 0.001"/>
      </geometry>
    </visual>
    <collision>
      <origin rpy="-1.5707963268 0 0" xyz="0 0 0"/>
      <geometry>
        <mesh filename="/home/remco/catkin_ws/src/delta_robot_simulation/meshes/lleg_link.dae" scale="0.001 0.001 0.001"/>
      </geometry>
    </collision>
  </link>
  <joint name="con2_lleg_1" type="continuous">
    <origin rpy="2.555702653 0 3.141592654" xyz="-0.052 -0.320 0"/>
    <parent link="uleg_1"/>
    <child link="lleg_12"/>
    <mimic joint="con_lleg_1"/>
    <axis xyz="-1 1 -1"/>
  </joint>
  <link name="lleg_12">
    <inertial>
      <origin rpy="1.5707963268 0 0" xyz="0 0 0 "/>
      <mass value="0.00001"/>
      <inertia ixx="0.00001" ixy="0.0" ixz="0.0" iyy="0.00001" iyz="0.0" izz="0.00001"/>
    </inertial>
    <visual>
      <origin rpy="1.5707963268 0 0" xyz="0 0 0"/>
      <geometry>
        <mesh filename="/home/remco/catkin_ws/src/delta_robot_simulation/meshes/lleg_link.dae" scale="0.001 0.001 0.001"/>
      </geometry>
    </visual>
    <collision>
      <origin rpy="1.5707963268 0 0" xyz="0 0 0"/>
      <geometry>
        <mesh filename="/home/remco/catkin_ws/src/delta_robot_simulation/meshes/lleg_link.dae" scale="0.001 0.001 0.001"/>
      </geometry>
    </collision>
  </link>
  <!--lleg2-->
  <joint name="con_lleg_2" type="continuous">
    <origin rpy="0.585890011 0 0" xyz="0.052 -0.320 0"/>
    <parent link="uleg_2"/>
    <child link="lleg_2"/>
    <axis xyz="1 1 1"/>
  </joint>
  <link name="lleg_2">
    <inertial>
      <origin rpy="-1.5707963268 0 0" xyz="0 0 0 "/>
      <mass value="0.00001"/>
      <inertia ixx="0.00001" ixy="0.0" ixz="0.0" iyy="0.00001" iyz="0.0" izz="0.00001"/>
    </inertial>
    <visual>
      <origin rpy="-1.5707963268 0 0" xyz="0 0 0"/>
      <geometry>
        <mesh filename="/home/remco/catkin_ws/src/delta_robot_simulation/meshes/lleg_link.dae" scale="0.001 0.001 0.001"/>
      </geometry>
    </visual>
    <collision>
      <origin rpy="-1.5707963268 0 0" xyz="0 0 0"/>
      <geometry>
        <mesh filename="/home/remco/catkin_ws/src/delta_robot_simulation/meshes/lleg_link.dae" scale="0.001 0.001 0.001"/>
      </geometry>
    </collision>
  </link>
  <joint name="con2_lleg_2" type="continuous">
    <origin rpy="2.555702653 0 3.141592654" xyz="-0.052 -0.320 0"/>
    <parent link="uleg_2"/>
    <child link="lleg_22"/>
    <mimic joint="con_lleg_2"/>
    <axis xyz="-1 1 -1"/>
  </joint>
  <link name="lleg_22">
    <inertial>
      <origin rpy="1.5707963268 0 0" xyz="0 0 0 "/>
      <mass value="0.00001"/>
      <inertia ixx="0.00001" ixy="0.0" ixz="0.0" iyy="0.00001" iyz="0.0" izz="0.00001"/>
    </inertial>
    <visual>
      <origin rpy="1.5707963268 0 0" xyz="0 0 0"/>
      <geometry>
        <mesh filename="/home/remco/catkin_ws/src/delta_robot_simulation/meshes/lleg_link.dae" scale="0.001 0.001 0.001"/>
      </geometry>
    </visual>
    <collision>
      <origin rpy="1.5707963268 0 0" xyz="0 0 0"/>
      <geometry>
        <mesh filename="/home/remco/catkin_ws/src/delta_robot_simulation/meshes/lleg_link.dae" scale="0.001 0.001 0.001"/>
      </geometry>
    </collision>
  </link>
  <!--lleg3-->
  <joint name="con_lleg_3" type="continuous">
    <origin rpy="0.585890011 0 0" xyz="0.052 -0.320 0"/>
    <parent link="uleg_3"/>
    <child link="lleg_3"/>
    <axis xyz="1 1 1"/>
  </joint>
  <link name="lleg_3">
    <inertial>
      <origin rpy="-1.5707963268 0 0" xyz="0 0 0 "/>
      <mass value="0.00001"/>
      <inertia ixx="0.00001" ixy="0.0" ixz="0.0" iyy="0.00001" iyz="0.0" izz="0.00001"/>
    </inertial>
    <visual>
      <origin rpy="-1.5707963268 0 0" xyz="0 0 0"/>
      <geometry>
        <mesh filename="/home/remco/catkin_ws/src/delta_robot_simulation/meshes/lleg_link.dae" scale="0.001 0.001 0.001"/>
      </geometry>
    </visual>
    <collision>
      <origin rpy="-1.5707963268 0 0" xyz="0 0 0"/>
      <geometry>
        <mesh filename="/home/remco/catkin_ws/src/delta_robot_simulation/meshes/lleg_link.dae" scale="0.001 0.001 0.001"/>
      </geometry>
    </collision>
  </link>
  <joint name="con2_lleg_3" type="continuous">
    <origin rpy="2.555702653 0 3.141592654" xyz="-0.052 -0.320 0"/>
    <parent link="uleg_3"/>
    <child link="lleg_32"/>
    <mimic joint="con_lleg_3"/>
    <axis xyz="-1 1 -1"/>
  </joint>
  <link name="lleg_32">
    <inertial>
      <origin rpy="1.5707963268 0 0" xyz="0 0 0 "/>
      <mass value="0.00001"/>
      <inertia ixx="0.00001" ixy="0.0" ixz="0.0" iyy="0.00001" iyz="0.0" izz="0.00001"/>
    </inertial>
    <visual>
      <origin rpy="1.5707963268 0 0" xyz="0 0 0"/>
      <geometry>
        <mesh filename="/home/remco/catkin_ws/src/delta_robot_simulation/meshes/lleg_link.dae" scale="0.001 0.001 0.001"/>
      </geometry>
    </visual>
    <collision>
      <origin rpy="1.5707963268 0 0" xyz="0 0 0"/>
      <geometry>
        <mesh filename="/home/remco/catkin_ws/src/delta_robot_simulation/meshes/lleg_link.dae" scale="0.001 0.001 0.001"/>
      </geometry>
    </collision>
  </link>
  <!-- base -->
  <link name="low_base">
    <inertial>
      <origin rpy="0 0 0" xyz="0 0 0"/>
      <mass value="0.001"/>
      <inertia ixx="0.00001" ixy="0.0" ixz="0.0" iyy="0.00001" iyz="0.0" izz="0.00001"/>
    </inertial>
    <visual>
      <origin rpy="0 0 0" xyz="0 0 0"/>
      <geometry>
        <mesh filename="/home/remco/catkin_ws/src/delta_robot_simulation/meshes/base_low_link.dae" scale="0.001 0.001 0.001"/>
      </geometry>
    </visual>
    <collision>
      <origin rpy="0 0 0" xyz="0 0 0"/>
      <geometry>
        <mesh filename="/home/remco/catkin_ws/src/delta_robot_simulation/meshes/base_low_link.dae" scale="0.001 0.001 0.001"/>
      </geometry>
    </collision>
  </link>

  <joint name="base_spawn" type="floating">
    <origin rpy="0 0 0" xyz="0 0 -0.710448"/>
    <parent link="base_link"/>
    <child link="low_base"/>
  </joint>

  <link name="A11">
    <inertial>
      <origin rpy="0 0 0" xyz="0 0 0"/>
      <mass value="0.00001"/>
      <inertia ixx="0.00001" ixy="0.0" ixz="0.0" iyy="0.00001" iyz="0.0" izz="0.00001"/>
    </inertial>
    <visual>
      <origin rpy="0 0 0" xyz="0 0 0"/>
      <geometry>
        <box size="0.01 0.01 0.01"/>
      </geometry>
    </visual>
  </link>
  <joint name="JA11" type="revolute">
    <origin rpy="0 0 0" xyz="0.052 -0.05 0"/>
    <parent link="low_base"/>
    <child link="A11"/>
    <limit lower="0" upper="0" effort="0" velocity="0"/>
    <axis xyz="1 0 0"/>
  </joint>

  <link name="A12">
    <inertial>
      <origin rpy="0 0 4.1887902048" xyz="0 0 0"/>
      <mass value="0.00001"/>
      <inertia ixx="0.00001" ixy="0.0" ixz="0.0" iyy="0.00001" iyz="0.0" izz="0.00001"/>
    </inertial>
    <visual>
      <origin rpy="0 0 0" xyz="0 0 0"/>
      <geometry>
        <box size="0.01 0.01 0.01"/>
      </geometry>
    </visual>
  </link>
  <joint name="JA12" type="revolute">
    <origin rpy="0 0 0" xyz="-0.052 -0.05 0"/>
    <parent link="low_base"/>
    <child link="A12"/>
    <limit lower="0" upper="0" effort="0" velocity="0"/>
    <axis xyz="1 0 0"/>
  </joint>

  <link name="A21">
    <inertial>
      <origin rpy="0 0 0" xyz="0 0 0"/>
      <mass value="0.00001"/>
      <inertia ixx="0.00001" ixy="0.0" ixz="0.0" iyy="0.00001" iyz="0.0" izz="0.00001"/>
    </inertial>
    <visual>
      <origin rpy="0 0 0" xyz="0 0 0"/>
      <geometry>
        <box size="0.01 0.01 0.01"/>
      </geometry>
    </visual>
  </link>
  <joint name="JA21" type="revolute">
    <origin rpy="0 0 4.1887902048" xyz="-0.01698 0.07059 0"/>
    <parent link="low_base"/>
    <child link="A21"/>
    <limit lower="0" upper="0" effort="0" velocity="0"/>
    <axis xyz="1 0 0"/>
  </joint>

  <link name="A22">
    <inertial>
      <origin rpy="0 0 0" xyz="0 0 0"/>
      <mass value="0.00001"/>
      <inertia ixx="0.00001" ixy="0.0" ixz="0.0" iyy="0.00001" iyz="0.0" izz="0.00001"/>
    </inertial>
    <visual>
      <origin rpy="0 0 0" xyz="0 0 0"/>
      <geometry>
        <box size="0.01 0.01 0.01"/>
      </geometry>
    </visual>
  </link>
  <joint name="JA22" type="revolute">
    <origin rpy="0 0 4.1887902048" xyz="-0.06962 -0.02059 0"/>
    <parent link="low_base"/>
    <child link="A22"/>
    <limit lower="0" upper="0" effort="0" velocity="0"/>
    <axis xyz="1 0 0"/>
  </joint>

  <link name="A31">
    <inertial>
      <origin rpy="0 0 0" xyz="0 0 0"/>
      <mass value="0.00001"/>
      <inertia ixx="0.00001" ixy="0.0" ixz="0.0" iyy="0.00001" iyz="0.0" izz="0.00001"/>
    </inertial>
    <visual>
      <origin rpy="0 0 0" xyz="0 0 0"/>
      <geometry>
        <box size="0.01 0.01 0.01"/>
      </geometry>
    </visual>
  </link>
  <joint name="JA31" type="revolute">
    <origin rpy="0 0 2.0943951024" xyz="0.06962 -0.02059 0"/>
    <parent link="low_base"/>
    <child link="A31"/>
    <limit lower="0" upper="0" effort="0" velocity="0"/>
    <axis xyz="1 0 0"/>
  </joint>

  <link name="A32">
    <inertial>
      <origin rpy="0 0 0" xyz="0 0 0"/>
      <mass value="0.00001"/>
      <inertia ixx="0.00001" ixy="0.0" ixz="0.0" iyy="0.00001" iyz="0.0" izz="0.00001"/>
    </inertial>
    <visual>
      <origin rpy="0 0 0" xyz="0 0 0"/>
      <geometry>
        <box size="0.01 0.01 0.01"/>
      </geometry>
    </visual>
  </link>
  <joint name="JA32" type="revolute">
    <origin rpy="0 0 2.0943951024" xyz="0.01698 0.07059 0"/>
    <parent link="low_base"/>
    <child link="A32"/>
    <limit lower="0" upper="0" effort="0" velocity="0"/>
    <axis xyz="1 0 0"/>
  </joint>

  <gazebo>
    <joint name="lleg11_base" type="ball">
      <child>lleg_1</child>
      <parent>A11</parent>
      <pose> 0 0 -0.850 0 0 0 </pose>
      <axis>
        <xyz>1 1 1</xyz>
        <limit>
          <lower>-100</lower>
          <upper>100</upper>
        </limit>
        <dynamics>
          <spring_reference>0</spring_reference>
          <spring_stiffness>0</spring_stiffness>
          <damping>0.000000</damping>
          <friction>0.00030000</friction>
        </dynamics>
        <use_parent_model_frame>0</use_parent_model_frame>
      </axis>
    </joint>
    <joint name="lleg12_base" type="ball">
      <child>lleg_12</child>
      <parent>A12</parent>
      <pose> 0 0 0.850 0 0 0 </pose>
      <axis>
        <xyz>-1 1 -1</xyz>
        <limit>
          <lower>-100</lower>
          <upper>100</upper>
        </limit>
        <dynamics>
          <spring_reference>0</spring_reference>
          <spring_stiffness>0</spring_stiffness>
          <damping>0.000000</damping>
          <friction>0.00030000</friction>
        </dynamics>
        <use_parent_model_frame>0</use_parent_model_frame>
      </axis>
    </joint>

    <joint name="lleg21_base" type="ball">
      <child>lleg_2</child>
      <parent>A21</parent>
      <pose> 0 0 -0.850 0 0 0 </pose>
      <axis>
        <xyz>1 1 1</xyz>
        <limit>
          <lower>-100</lower>
          <upper>100</upper>
        </limit>
        <dynamics>
          <spring_reference>0</spring_reference>
          <spring_stiffness>0</spring_stiffness>
          <damping>0.000000</damping>
          <friction>0.00030000</friction>
        </dynamics>
        <use_parent_model_frame>0</use_parent_model_frame>
      </axis>
    </joint>
    <joint name="lleg22_base" type="ball">
      <child>lleg_22</child>
      <parent>A22</parent>
      <pose> 0 0 0.850 0 0 0 </pose>
      <axis>
        <xyz>-1 1 -1</xyz>
        <limit>
          <lower>-100</lower>
          <upper>100</upper>
        </limit>
        <dynamics>
          <spring_reference>0</spring_reference>
          <spring_stiffness>0</spring_stiffness>
          <damping>0.000000</damping>
          <friction>0.00030000</friction>
        </dynamics>
        <use_parent_model_frame>0</use_parent_model_frame>
      </axis>
    </joint>

    <joint name="lleg31_base" type="ball">
      <child>lleg_3</child>
      <parent>A31</parent>
      <pose> 0 0 -0.850 0 0 0 </pose>
      <axis>
        <xyz>1 1 1</xyz>
        <limit>
          <lower>-100</lower>
          <upper>100</upper>
        </limit>
        <dynamics>
          <spring_reference>0</spring_reference>
          <spring_stiffness>0</spring_stiffness>
          <damping>0.000000</damping>
          <friction>0.00030000</friction>
        </dynamics>
        <use_parent_model_frame>0</use_parent_model_frame>
      </axis>
    </joint>
    <joint name="lleg32_base" type="ball">
      <child>lleg_32</child>
      <parent>A32</parent>
      <pose> 0 0 0.850 0 0 0 </pose>
      <axis>
        <xyz>-1 1 -1</xyz>
        <limit>
          <lower>-100</lower>
          <upper>100</upper>
        </limit>
        <dynamics>
          <spring_reference>0</spring_reference>
          <spring_stiffness>0</spring_stiffness>
          <damping>0.000000</damping>
          <friction>0.00030000</friction>
        </dynamics>
        <use_parent_model_frame>0</use_parent_model_frame>
      </axis>
    </joint>
  </gazebo>

    <!--<link name="ee_link">
      <visual>
        <geometry>
          <sphere radius="0.01"/>
        </geometry>
        <material name="Gazebo/Grey">
          <color rgba="0. 0. 0. 1"/>
        </material>
      </visual>
    </link>
    <gazebo reference="ee_link">
      <material>Gazebo/Blue</material>
      <selfCollide>False</selfCollide>
    </gazebo>
    <joint name="ee_link" type="fixed">
      <origin rpy="0 -1.57 0" xyz="-0.03 0.027 -0.04"/>
      <parent link="low_base"/>
      <child link="ee_link"/>
    </joint>

    <link name="goal_point">
      <visual>
        <geometry>
          <sphere radius="0.01"/>
        </geometry>
        <material name="Gazebo/Grey">
          <color rgba="0. 1. 0. 1"/>
        </material>
      </visual>
    </link>
    <gazebo reference="goal_point">
      <material>Gazebo/Blue</material>
      <selfCollide>False</selfCollide>
    </gazebo>
    <joint name= "link_0__goal_point" type="fixed">
      <origin rpy="0 0 0" xyz="0.2 0.2 -0.5"/>
      <parent link="link_0"/>
      <child link="goal_point"/>
    </joint>

  <gazebo>      
    <plugin name="joint_state_publisher" filename="libgazebo_ros_joint_state_publisher.so">
      <robotNamespace>delta_robot</robotNamespace>
      <joint_name>motor1</joint_name>
      <joint_name>motor2</joint_name>
      <joint_name>motor3</joint_name>
      <updateRate>100</updateRate>
      <alwaysOn>true</alwaysOn>
    </plugin>
  </gazebo>

  <gazebo>      
    <plugin name="gazebo_ros_joint_pose_trajectory" filename="libgazebo_ros_joint_pose_trajectory.so">
      <robotNamespace>delta_robot</robotNamespace>
      <updateRate>2</updateRate>
    </plugin>
  </gazebo>-->

  <!--<gazebo>
      <plugin name="delta_robot_control" filename="libdelta_robot_plugin.so">
      <p>1</p>
      <i>0</i>
      <d>0</d>
    </plugin>
  </gazebo>-->
</robot>
